#VRML_SIM R2023b utf8

EXTERNPROTO "https://raw.githubusercontent.com/cyberbotics/webots/R2022b/projects/objects/backgrounds/protos/TexturedBackground.proto"
EXTERNPROTO "https://raw.githubusercontent.com/cyberbotics/webots/R2022b/projects/objects/backgrounds/protos/TexturedBackgroundLight.proto"
EXTERNPROTO "https://raw.githubusercontent.com/tjacobs131/Agrobot/main/protos/PlanterBox.proto"
EXTERNPROTO "https://raw.githubusercontent.com/cyberbotics/webots/released/projects/objects/floors/protos/RectangleArena.proto"

WorldInfo {
  contactProperties [
    ContactProperties {
      coulombFriction [
        8
      ]
      softCFM 1e-05
      bumpSound ""
      rollSound ""
      slideSound ""
    }
    ContactProperties {
      # Material for frictionless spheres

      material1 "SwivelWheelMaterial"  # The contactMaterial you defined for the swivel wheels
      coulombFriction 0.02 # The friction coefficient
      bounce 0  # The restitution coefficient (0 means no bounce)
      softERP 0.4 # The error reduction parameter (0 means no correction)
      softCFM 0.001  # The constraint force mixing parameter (0 means a hard constraint)
    }
    ContactProperties {
      # Material for motorized wheels

      material1 "DrivingWheelMaterial"  # The contactMaterial you defined for the swivel wheels
      coulombFriction .2 # The friction coefficient
      bounce 0  # The restitution coefficient (0 means no bounce)
      softERP 0.8 # The error reduction parameter (0 means no correction)
      softCFM 0.0001  # The constraint force mixing parameter (0 means a hard constraint)
    }
  ]
}
Viewpoint {
  orientation -0.028111941427640622 -0.025786144481606803 -0.999272131854953 1.6577717305151745
  position 17.42 24.02149532652635 2.5200000000000102
  follow "Agrobot"
}
TexturedBackground {
}
TexturedBackgroundLight {
}
RectangleArena {
  translation -2.67 0 0
  floorSize 200 200
  floorTileSize 10 10
  wallHeight 10
}
Robot {
  translation 0 1 2
  children [
    Transform {
      translation 0 0 1
      rotation 1 0 0 1.5708
      scale 0.01 0.01 0.01
      children [
        Shape {
          appearance PBRAppearance {
            baseColor 0.9 0.9 0.9
            roughness 1
            metalness 0
          }
          geometry DEF MY_ROBOT_SHAPE Mesh {
            url [
              "https://raw.githubusercontent.com/tjacobs131/Agrobot/main/resource/agrobot_model.obj"
            ]
          }
        }
      ]
    }
    DEF WHEEL1 HingeJoint {
      jointParameters HingeJointParameters {
        axis 0 1 0
        anchor -3.1 -0.5 1.5
        stopCFM 0.01
        stopERP 1
      }
      device [
        RotationalMotor {
          name "left wheel motor"
          maxVelocity 5000
          maxTorque 200
        }
      ]
      endPoint Solid {
        translation -3.1 -0.5 1.5
        rotation 1 0 0 1.57084
        contactMaterial "DrivingWheelMaterial"
        children [
          DEF WHEEL Shape {
            appearance PBRAppearance {
              baseColor 0.305882 0.898039 0.25098
              roughness 1
              metalness 0
            }
            geometry Cylinder {
              height 1
              radius 2
              subdivision 24
            }
          }
        ]
        boundingObject USE WHEEL
        physics Physics {
          density 500
        }
      }
    }
    DEF WHEEL2 HingeJoint {
      jointParameters HingeJointParameters {
        axis 0 1 0
        anchor -3.1 13.5 1.5
        stopCFM 0.01
        stopERP 1
      }
      device [
        RotationalMotor {
          name "right wheel motor"
          maxVelocity 5000
          maxTorque 200
        }
      ]
      endPoint Solid {
        translation -3.1 13.5 1.5
        rotation 1 0 0 1.5708
        contactMaterial "DrivingWheelMaterial"
        children [
          DEF WHEEL Shape {
            appearance PBRAppearance {
              baseColor 0.305882 0.898039 0.25098
              roughness 1
              metalness 0
            }
            geometry Cylinder {
              height 1
              radius 2
              subdivision 24
            }
          }
        ]
        boundingObject USE WHEEL
        physics Physics {
          density 500
        }
      }
    }
    Solid {
      translation 9.32 0.07 0.54
      contactMaterial "SwivelWheelMaterial"
      children [
        DEF SWIVEL Shape {
          appearance PBRAppearance {
            baseColor 0.9 0.9 0.9
            roughness 1
            metalness 0
          }
          geometry Sphere {
          }
        }
      ]
      name "swivelWheel1"
      boundingObject USE SWIVEL
      physics Physics {
        mass 100
      }
    }
    Solid {
      translation 9.32 12.67 0.54
      contactMaterial "SwivelWheelMaterial"
      children [
        DEF SWIVEL Shape {
          appearance PBRAppearance {
            baseColor 0.9 0.9 0.9
            roughness 1
            metalness 0
          }
          geometry Sphere {
          }
        }
      ]
      name "swivelWheel2"
      boundingObject USE SWIVEL
      physics Physics {
        mass 100
      }
    }
  ]
  name "Agrobot"
  physics Physics {
    mass .1
  }
  controller "<extern>"
}
PlanterBox {
  translation -27.5 -7.5 0.2
}
PlanterBox {
  translation -12.5 -7.5 0.2
}
PlanterBox {
  translation -27.5 7.5 0.2
}
PlanterBox {
  translation -12.5 7.5 0.2
}