#VRML_SIM R2023b utf8

EXTERNPROTO "https://raw.githubusercontent.com/cyberbotics/webots/R2022b/projects/objects/backgrounds/protos/TexturedBackground.proto"
EXTERNPROTO "https://raw.githubusercontent.com/cyberbotics/webots/R2022b/projects/objects/backgrounds/protos/TexturedBackgroundLight.proto"
EXTERNPROTO "https://raw.githubusercontent.com/tjacobs131/Agrobot/main/protos/PlanterBox.proto"
EXTERNPROTO "https://raw.githubusercontent.com/cyberbotics/webots/released/projects/objects/floors/protos/RectangleArena.proto"

WorldInfo {
  contactProperties [
    ContactProperties {
      coulombFriction [
        8
      ]
      softCFM 1e-05
      bumpSound ""
      rollSound ""
      slideSound ""
    }
  ]
}
Viewpoint {
  orientation -0.09466797046522717 0.6191123164564357 0.7795754709968375 0.47399286842069965
  position -1386.715565989851 -242.23618971788403 342.16232302704464
  follow "Agrobot"
}
TexturedBackground {
}
TexturedBackgroundLight {
}

RectangleArena {
  floorSize 200 200
  floorTileSize 10 10
  wallHeight 10

  physics Physics{
  }
}
Robot {
  children [
    Transform {
      translation 0 0 50
      rotation 1 0 0 1.5708
      scale 0.01 0.01 0.01
      children [
        Shape {
          appearance PBRAppearance {
            baseColor 0.9 0.9 0.9
            roughness 1
            metalness 0
          }
          geometry DEF MY_ROBOT_SHAPE Mesh {
            url [
              "/home/tjacobs/ros2_ws/install/agrobot_pkg/share/agrobot_pkg/worlds/../resource/agrobot_model.obj"
            ]
          }
        }
      ]
    }
    DEF WHEEL1 HingeJoint {
      jointParameters HingeJointParameters {
        axis 0 1 0
        anchor 0.05 0.06 0
      }
      device [
        RotationalMotor {
          name "wheel1"
        }
      ]
      endPoint Solid {
        translation -31.62 -5.64019 53.11
        rotation 1 0 0 1.5708
        children [
          DEF WHEEL Shape {
            appearance PBRAppearance {
              baseColor 0.305882 0.898039 0.25098
              roughness 1
              metalness 0
            }
            geometry Cylinder {
              height 1
              radius 2
              subdivision 24
            }
          }
        ]
        boundingObject USE WHEEL
        physics Physics {
          density 1000
        }
      }
    }
    DEF WHEEL2 HingeJoint {
      jointParameters HingeJointParameters {
        axis 0 1 0
        anchor 0.05 0.06 0
      }
      device [
        RotationalMotor {
          name "wheel1"
        }
      ]
      endPoint Solid {
        translation -31.62 135.55 53.1101
        rotation 1 0 0 1.5708
        children [
          DEF WHEEL Shape {
            appearance PBRAppearance {
              baseColor 0.305882 0.898039 0.25098
              roughness 1
              metalness 0
            }
            geometry Cylinder {
              height 1
              radius 2
              subdivision 24
            }
          }
        ]
        name "solid(1)"
        boundingObject USE WHEEL
        physics Physics {
          density 1000
        }
      }
    }
  ]
  name "Agrobot"
  physics Physics {
    mass 1000
  }
  controller "<extern>"
}
PlanterBox {
  translation -75 -75 2
}
PlanterBox {
  translation 75 -75 2
}
PlanterBox {
  translation -75 75 2
}
PlanterBox {
  translation 75 75 2
}
